/u/utd8hj/Documents/FedScale/fedscale/core/resource_manager.py:33: SyntaxWarning: assertion is always true, perhaps remove parentheses?
  assert(client_id in self.client_run_queue,
(10-13) 19:35:58 INFO     [aggregator.py:33] Job args Namespace(adam_epsilon=1e-08, arrival_interval=3, async_buffer=10, async_mode=False, backbone='./resnet50.pth', backend='gloo', batch_size=20, bidirectional=True, blacklist_max_len=0.3, blacklist_rounds=-1, block_size=64, cfg_file='./utils/rcnn/cfgs/res101.yml', checkin_period=50, clf_block_size=32, clip_bound=0.9, clip_threshold=3.0, clock_factor=1.0, conf_path='~/dataset/', connection_timeout=60, cuda_device=None, cut_off_util=0.05, data_cache='', data_dir='/u/utd8hj/Documents/FedScale/benchmark/dataset/data/MHEALTH', data_map_file='/u/utd8hj/Documents/FedScale/benchmark/dataset/data/MHEALTH/client_data_mapping/train.csv', data_set='MHEALTH', decay_factor=0.98, decay_round=10, device_avail_file='/u/utd8hj/Documents/FedScale/benchmark/dataset/data/device_info/client_behave_trace', device_conf_file='/u/utd8hj/Documents/FedScale/benchmark/dataset/data/device_info/client_device_capacity', dump_epoch=10000000000.0, embedding_file='glove.840B.300d.txt', engine='pytorch', epsilon=0.9, eval_interval=10, executor_configs='127.0.1.1:[4]', experiment_mode='simulation', exploration_alpha=0.3, exploration_decay=0.98, exploration_factor=0.9, exploration_min=0.3, filter_less=21, filter_more=1000000000000000.0, finetune=False, gamma=0.9, gradient_policy=None, hidden_layers=7, hidden_size=256, input_dim=22, job_name='MHEALTH_demo', labels_path='labels.json', learning_rate=0.05, line_by_line=False, local_steps=5, log_path='/u/utd8hj/Documents/FedScale/benchmark', loss_decay=0.2, malicious_factor=1000000000000000.0, max_concurrency=100, max_staleness=5, memory_capacity=2000, min_learning_rate=5e-05, mlm=False, mlm_probability=0.15, model='lr', model_size=65536, model_zoo='torchcv', n_actions=2, n_states=4, noise_dir=None, noise_factor=0.1, noise_max=0.5, noise_min=0.0, noise_prob=0.4, num_class=13, num_classes=13, num_executors=4, num_loaders=2, num_participants=50, output_dim=0, overcommitment=1.3, overwrite_cache=False, pacer_delta=5, pacer_step=20, proxy_mu=0.1, ps_ip='127.0.1.1', ps_port='29501', rnn_type='lstm', round_penalty=2.0, round_threshold=30, rounds=200, sample_mode='random', sample_rate=16000, sample_seed=233, sample_window=5.0, spec_augment=False, speed_volume_perturb=False, target_delta=0.0001, target_replace_iter=15, task='cv', test_bsz=20, test_manifest='data/test_manifest.csv', test_output_dir='./logs/server', test_ratio=1.0, test_size_file='', this_rank=0, time_stamp='1013_193527', train_manifest='data/train_manifest.csv', train_size_file='', train_uniform=False, upload_step=20, use_cuda=True, vocab_tag_size=500, vocab_token_size=10000, weight_decay=0, window='hamming', window_size=0.02, window_stride=0.01, yogi_beta=0.9, yogi_beta2=0.99, yogi_eta=0.003, yogi_tau=1e-08)
(10-13) 19:35:59 INFO     [executor.py:61] (EXECUTOR:2) is setting up environ ...
(10-13) 19:35:59 INFO     [executor.py:61] (EXECUTOR:1) is setting up environ ...
(10-13) 19:35:59 INFO     [executor.py:61] (EXECUTOR:4) is setting up environ ...
(10-13) 19:35:59 INFO     [executor.py:61] (EXECUTOR:3) is setting up environ ...
2022-10-13 19:36:01.536699: I tensorflow/core/platform/cpu_feature_guard.cc:193] This TensorFlow binary is optimized with oneAPI Deep Neural Network Library (oneDNN) to use the following CPU instructions in performance-critical operations:  AVX2 AVX512F AVX512_VNNI FMA
To enable them in other operations, rebuild TensorFlow with the appropriate compiler flags.
(10-13) 19:36:06 INFO     [executor.py:117] Data partitioner starts ...
(10-13) 19:36:06 INFO     [divide_data.py:63] Partitioning data by profile /u/utd8hj/Documents/FedScale/benchmark/dataset/data/MHEALTH/client_data_mapping/train.csv...
(10-13) 19:36:06 INFO     [divide_data.py:75] Trace names are client_Id, chest_acc_x, chest_acc_y, chest_acc_z, ecg_1, ecg_2, left_ankle_acc_x, left_ankle_acc_y, left_ankle_acc_z, left_ankle_gyro_x, left_ankle_gyro_y, left_ankle_gyro_z, left_ankle_mag_x, left_ankle_mag_y, left_ankle_mag_z, right_arm_acc_x, right_arm_acc_y, right_arm_acc_z, right_arm_gyro_x, right_arm_gyro_y, right_arm_gyro_z, right_arm_mag_x, right_arm_mag_y, right_arm_mag_z, label_Id
(10-13) 19:36:06 INFO     [executor.py:117] Data partitioner starts ...
(10-13) 19:36:06 INFO     [divide_data.py:63] Partitioning data by profile /u/utd8hj/Documents/FedScale/benchmark/dataset/data/MHEALTH/client_data_mapping/train.csv...
(10-13) 19:36:06 INFO     [divide_data.py:75] Trace names are client_Id, chest_acc_x, chest_acc_y, chest_acc_z, ecg_1, ecg_2, left_ankle_acc_x, left_ankle_acc_y, left_ankle_acc_z, left_ankle_gyro_x, left_ankle_gyro_y, left_ankle_gyro_z, left_ankle_mag_x, left_ankle_mag_y, left_ankle_mag_z, right_arm_acc_x, right_arm_acc_y, right_arm_acc_z, right_arm_gyro_x, right_arm_gyro_y, right_arm_gyro_z, right_arm_mag_x, right_arm_mag_y, right_arm_mag_z, label_Id
(10-13) 19:36:06 INFO     [executor.py:117] Data partitioner starts ...
(10-13) 19:36:06 INFO     [divide_data.py:63] Partitioning data by profile /u/utd8hj/Documents/FedScale/benchmark/dataset/data/MHEALTH/client_data_mapping/train.csv...
(10-13) 19:36:06 INFO     [executor.py:117] Data partitioner starts ...
(10-13) 19:36:06 INFO     [divide_data.py:63] Partitioning data by profile /u/utd8hj/Documents/FedScale/benchmark/dataset/data/MHEALTH/client_data_mapping/train.csv...
(10-13) 19:36:06 INFO     [divide_data.py:75] Trace names are client_Id, chest_acc_x, chest_acc_y, chest_acc_z, ecg_1, ecg_2, left_ankle_acc_x, left_ankle_acc_y, left_ankle_acc_z, left_ankle_gyro_x, left_ankle_gyro_y, left_ankle_gyro_z, left_ankle_mag_x, left_ankle_mag_y, left_ankle_mag_z, right_arm_acc_x, right_arm_acc_y, right_arm_acc_z, right_arm_gyro_x, right_arm_gyro_y, right_arm_gyro_z, right_arm_mag_x, right_arm_mag_y, right_arm_mag_z, label_Id
(10-13) 19:36:06 INFO     [divide_data.py:75] Trace names are client_Id, chest_acc_x, chest_acc_y, chest_acc_z, ecg_1, ecg_2, left_ankle_acc_x, left_ankle_acc_y, left_ankle_acc_z, left_ankle_gyro_x, left_ankle_gyro_y, left_ankle_gyro_z, left_ankle_mag_x, left_ankle_mag_y, left_ankle_mag_z, right_arm_acc_x, right_arm_acc_y, right_arm_acc_z, right_arm_gyro_x, right_arm_gyro_y, right_arm_gyro_z, right_arm_mag_x, right_arm_mag_y, right_arm_mag_z, label_Id
2022-10-13 19:36:07.161728: I tensorflow/core/util/util.cc:169] oneDNN custom operations are on. You may see slightly different numerical results due to floating-point round-off errors from different computation orders. To turn them off, set the environment variable `TF_ENABLE_ONEDNN_OPTS=0`.
(10-13) 19:36:07 INFO     [divide_data.py:106] Randomly partitioning data, 24333 samples...
(10-13) 19:36:07 INFO     [executor.py:128] Data partitioner completes ...
(10-13) 19:36:07 INFO     [channel_context.py:21] %%%%%%%%%% Opening grpc connection to 127.0.1.1 %%%%%%%%%%
(10-13) 19:36:07 INFO     [divide_data.py:106] Randomly partitioning data, 24333 samples...
(10-13) 19:36:07 INFO     [divide_data.py:106] Randomly partitioning data, 24333 samples...
(10-13) 19:36:07 INFO     [executor.py:128] Data partitioner completes ...
(10-13) 19:36:07 INFO     [channel_context.py:21] %%%%%%%%%% Opening grpc connection to 127.0.1.1 %%%%%%%%%%
(10-13) 19:36:07 INFO     [executor.py:128] Data partitioner completes ...
(10-13) 19:36:07 INFO     [channel_context.py:21] %%%%%%%%%% Opening grpc connection to 127.0.1.1 %%%%%%%%%%
(10-13) 19:36:07 INFO     [divide_data.py:106] Randomly partitioning data, 24333 samples...
(10-13) 19:36:07 INFO     [executor.py:128] Data partitioner completes ...
(10-13) 19:36:07 INFO     [channel_context.py:21] %%%%%%%%%% Opening grpc connection to 127.0.1.1 %%%%%%%%%%
(10-13) 19:36:07 INFO     [executor.py:414] Start monitoring events ...
(10-13) 19:36:07 INFO     [executor.py:414] Start monitoring events ...
(10-13) 19:36:07 INFO     [executor.py:414] Start monitoring events ...
(10-13) 19:36:07 INFO     [executor.py:414] Start monitoring events ...
(10-13) 19:36:07 WARNING  [executor.py:399] Failed to connect to aggregator <_InactiveRpcError of RPC that terminated with:
	status = StatusCode.UNAVAILABLE
	details = "failed to connect to all addresses"
	debug_error_string = "{"created":"@1665704167.517918010","description":"Failed to pick subchannel","file":"src/core/ext/filters/client_channel/client_channel.cc","file_line":3186,"referenced_errors":[{"created":"@1665704167.517917447","description":"failed to connect to all addresses","file":"src/core/lib/transport/error_utils.cc","file_line":146,"grpc_status":14}]}"
>. Will retry in 5 sec.
(10-13) 19:36:07 WARNING  [executor.py:399] Failed to connect to aggregator <_InactiveRpcError of RPC that terminated with:
	status = StatusCode.UNAVAILABLE
	details = "failed to connect to all addresses"
	debug_error_string = "{"created":"@1665704167.517981531","description":"Failed to pick subchannel","file":"src/core/ext/filters/client_channel/client_channel.cc","file_line":3186,"referenced_errors":[{"created":"@1665704167.517981115","description":"failed to connect to all addresses","file":"src/core/lib/transport/error_utils.cc","file_line":146,"grpc_status":14}]}"
>. Will retry in 5 sec.
(10-13) 19:36:07 WARNING  [executor.py:399] Failed to connect to aggregator <_InactiveRpcError of RPC that terminated with:
	status = StatusCode.UNAVAILABLE
	details = "failed to connect to all addresses"
	debug_error_string = "{"created":"@1665704167.517918030","description":"Failed to pick subchannel","file":"src/core/ext/filters/client_channel/client_channel.cc","file_line":3186,"referenced_errors":[{"created":"@1665704167.517917473","description":"failed to connect to all addresses","file":"src/core/lib/transport/error_utils.cc","file_line":146,"grpc_status":14}]}"
>. Will retry in 5 sec.
(10-13) 19:36:07 WARNING  [executor.py:399] Failed to connect to aggregator <_InactiveRpcError of RPC that terminated with:
	status = StatusCode.UNAVAILABLE
	details = "failed to connect to all addresses"
	debug_error_string = "{"created":"@1665704167.517980670","description":"Failed to pick subchannel","file":"src/core/ext/filters/client_channel/client_channel.cc","file_line":3186,"referenced_errors":[{"created":"@1665704167.517980217","description":"failed to connect to all addresses","file":"src/core/lib/transport/error_utils.cc","file_line":146,"grpc_status":14}]}"
>. Will retry in 5 sec.
2022-10-13 19:36:08.733308: W tensorflow/stream_executor/platform/default/dso_loader.cc:64] Could not load dynamic library 'libcudart.so.11.0'; dlerror: libcudart.so.11.0: cannot open shared object file: No such file or directory
2022-10-13 19:36:08.733345: I tensorflow/stream_executor/cuda/cudart_stub.cc:29] Ignore above cudart dlerror if you do not have a GPU set up on your machine.
2022-10-13 19:36:09.382210: E tensorflow/stream_executor/cuda/cuda_blas.cc:2981] Unable to register cuBLAS factory: Attempting to register factory for plugin cuBLAS when one has already been registered
(10-13) 19:36:12 WARNING  [executor.py:399] Failed to connect to aggregator <_InactiveRpcError of RPC that terminated with:
	status = StatusCode.UNAVAILABLE
	details = "failed to connect to all addresses"
	debug_error_string = "{"created":"@1665704172.523115401","description":"Failed to pick subchannel","file":"src/core/ext/filters/client_channel/client_channel.cc","file_line":3186,"referenced_errors":[{"created":"@1665704172.523113706","description":"failed to connect to all addresses","file":"src/core/lib/transport/error_utils.cc","file_line":146,"grpc_status":14}]}"
>. Will retry in 5 sec.
(10-13) 19:36:12 WARNING  [executor.py:399] Failed to connect to aggregator <_InactiveRpcError of RPC that terminated with:
	status = StatusCode.UNAVAILABLE
	details = "failed to connect to all addresses"
	debug_error_string = "{"created":"@1665704172.523989672","description":"Failed to pick subchannel","file":"src/core/ext/filters/client_channel/client_channel.cc","file_line":3186,"referenced_errors":[{"created":"@1665704172.523988423","description":"failed to connect to all addresses","file":"src/core/lib/transport/error_utils.cc","file_line":146,"grpc_status":14}]}"
>. Will retry in 5 sec.
(10-13) 19:36:12 WARNING  [executor.py:399] Failed to connect to aggregator <_InactiveRpcError of RPC that terminated with:
	status = StatusCode.UNAVAILABLE
	details = "failed to connect to all addresses"
	debug_error_string = "{"created":"@1665704172.523885295","description":"Failed to pick subchannel","file":"src/core/ext/filters/client_channel/client_channel.cc","file_line":3186,"referenced_errors":[{"created":"@1665704172.523884033","description":"failed to connect to all addresses","file":"src/core/lib/transport/error_utils.cc","file_line":146,"grpc_status":14}]}"
>. Will retry in 5 sec.
(10-13) 19:36:12 WARNING  [executor.py:399] Failed to connect to aggregator <_InactiveRpcError of RPC that terminated with:
	status = StatusCode.UNAVAILABLE
	details = "failed to connect to all addresses"
	debug_error_string = "{"created":"@1665704172.523841796","description":"Failed to pick subchannel","file":"src/core/ext/filters/client_channel/client_channel.cc","file_line":3186,"referenced_errors":[{"created":"@1665704172.523840516","description":"failed to connect to all addresses","file":"src/core/lib/transport/error_utils.cc","file_line":146,"grpc_status":14}]}"
>. Will retry in 5 sec.
(10-13) 19:36:17 WARNING  [executor.py:399] Failed to connect to aggregator <_InactiveRpcError of RPC that terminated with:
	status = StatusCode.UNAVAILABLE
	details = "failed to connect to all addresses"
	debug_error_string = "{"created":"@1665704177.526980214","description":"Failed to pick subchannel","file":"src/core/ext/filters/client_channel/client_channel.cc","file_line":3186,"referenced_errors":[{"created":"@1665704177.526978752","description":"failed to connect to all addresses","file":"src/core/lib/transport/error_utils.cc","file_line":146,"grpc_status":14}]}"
>. Will retry in 5 sec.
(10-13) 19:36:17 WARNING  [executor.py:399] Failed to connect to aggregator <_InactiveRpcError of RPC that terminated with:
	status = StatusCode.UNAVAILABLE
	details = "failed to connect to all addresses"
	debug_error_string = "{"created":"@1665704177.526980329","description":"Failed to pick subchannel","file":"src/core/ext/filters/client_channel/client_channel.cc","file_line":3186,"referenced_errors":[{"created":"@1665704177.526978731","description":"failed to connect to all addresses","file":"src/core/lib/transport/error_utils.cc","file_line":146,"grpc_status":14}]}"
>. Will retry in 5 sec.
(10-13) 19:36:17 WARNING  [executor.py:399] Failed to connect to aggregator <_InactiveRpcError of RPC that terminated with:
	status = StatusCode.UNAVAILABLE
	details = "failed to connect to all addresses"
	debug_error_string = "{"created":"@1665704177.527930427","description":"Failed to pick subchannel","file":"src/core/ext/filters/client_channel/client_channel.cc","file_line":3186,"referenced_errors":[{"created":"@1665704177.527929216","description":"failed to connect to all addresses","file":"src/core/lib/transport/error_utils.cc","file_line":146,"grpc_status":14}]}"
>. Will retry in 5 sec.
(10-13) 19:36:17 WARNING  [executor.py:399] Failed to connect to aggregator <_InactiveRpcError of RPC that terminated with:
	status = StatusCode.UNAVAILABLE
	details = "failed to connect to all addresses"
	debug_error_string = "{"created":"@1665704177.527930496","description":"Failed to pick subchannel","file":"src/core/ext/filters/client_channel/client_channel.cc","file_line":3186,"referenced_errors":[{"created":"@1665704177.527929230","description":"failed to connect to all addresses","file":"src/core/lib/transport/error_utils.cc","file_line":146,"grpc_status":14}]}"
>. Will retry in 5 sec.
(10-13) 19:36:22 WARNING  [executor.py:399] Failed to connect to aggregator <_InactiveRpcError of RPC that terminated with:
	status = StatusCode.UNAVAILABLE
	details = "failed to connect to all addresses"
	debug_error_string = "{"created":"@1665704182.530867738","description":"Failed to pick subchannel","file":"src/core/ext/filters/client_channel/client_channel.cc","file_line":3186,"referenced_errors":[{"created":"@1665704182.530866148","description":"failed to connect to all addresses","file":"src/core/lib/transport/error_utils.cc","file_line":146,"grpc_status":14}]}"
>. Will retry in 5 sec.
(10-13) 19:36:22 WARNING  [executor.py:399] Failed to connect to aggregator <_InactiveRpcError of RPC that terminated with:
	status = StatusCode.UNAVAILABLE
	details = "failed to connect to all addresses"
	debug_error_string = "{"created":"@1665704182.530867675","description":"Failed to pick subchannel","file":"src/core/ext/filters/client_channel/client_channel.cc","file_line":3186,"referenced_errors":[{"created":"@1665704182.530866198","description":"failed to connect to all addresses","file":"src/core/lib/transport/error_utils.cc","file_line":146,"grpc_status":14}]}"
>. Will retry in 5 sec.
(10-13) 19:36:22 WARNING  [executor.py:399] Failed to connect to aggregator <_InactiveRpcError of RPC that terminated with:
	status = StatusCode.UNAVAILABLE
	details = "failed to connect to all addresses"
	debug_error_string = "{"created":"@1665704182.531814091","description":"Failed to pick subchannel","file":"src/core/ext/filters/client_channel/client_channel.cc","file_line":3186,"referenced_errors":[{"created":"@1665704182.531812815","description":"failed to connect to all addresses","file":"src/core/lib/transport/error_utils.cc","file_line":146,"grpc_status":14}]}"
>. Will retry in 5 sec.
(10-13) 19:36:22 WARNING  [executor.py:399] Failed to connect to aggregator <_InactiveRpcError of RPC that terminated with:
	status = StatusCode.UNAVAILABLE
	details = "failed to connect to all addresses"
	debug_error_string = "{"created":"@1665704182.531814066","description":"Failed to pick subchannel","file":"src/core/ext/filters/client_channel/client_channel.cc","file_line":3186,"referenced_errors":[{"created":"@1665704182.531812879","description":"failed to connect to all addresses","file":"src/core/lib/transport/error_utils.cc","file_line":146,"grpc_status":14}]}"
>. Will retry in 5 sec.
2022-10-13 19:36:24.507865: W tensorflow/stream_executor/platform/default/dso_loader.cc:64] Could not load dynamic library 'libnvinfer.so.7'; dlerror: libnvinfer.so.7: cannot open shared object file: No such file or directory
2022-10-13 19:36:24.508378: W tensorflow/stream_executor/platform/default/dso_loader.cc:64] Could not load dynamic library 'libnvinfer_plugin.so.7'; dlerror: libnvinfer_plugin.so.7: cannot open shared object file: No such file or directory
2022-10-13 19:36:24.508402: W tensorflow/compiler/tf2tensorrt/utils/py_utils.cc:38] TF-TRT Warning: Cannot dlopen some TensorRT libraries. If you would like to use Nvidia GPU with TensorRT, please make sure the missing libraries mentioned above are installed properly.
(10-13) 19:36:27 WARNING  [executor.py:399] Failed to connect to aggregator <_InactiveRpcError of RPC that terminated with:
	status = StatusCode.UNAVAILABLE
	details = "failed to connect to all addresses"
	debug_error_string = "{"created":"@1665704187.534972719","description":"Failed to pick subchannel","file":"src/core/ext/filters/client_channel/client_channel.cc","file_line":3186,"referenced_errors":[{"created":"@1665704187.534971219","description":"failed to connect to all addresses","file":"src/core/lib/transport/error_utils.cc","file_line":146,"grpc_status":14}]}"
>. Will retry in 5 sec.
(10-13) 19:36:27 WARNING  [executor.py:399] Failed to connect to aggregator <_InactiveRpcError of RPC that terminated with:
	status = StatusCode.UNAVAILABLE
	details = "failed to connect to all addresses"
	debug_error_string = "{"created":"@1665704187.534972759","description":"Failed to pick subchannel","file":"src/core/ext/filters/client_channel/client_channel.cc","file_line":3186,"referenced_errors":[{"created":"@1665704187.534971315","description":"failed to connect to all addresses","file":"src/core/lib/transport/error_utils.cc","file_line":146,"grpc_status":14}]}"
>. Will retry in 5 sec.
(10-13) 19:36:27 WARNING  [executor.py:399] Failed to connect to aggregator <_InactiveRpcError of RPC that terminated with:
	status = StatusCode.UNAVAILABLE
	details = "failed to connect to all addresses"
	debug_error_string = "{"created":"@1665704187.535855577","description":"Failed to pick subchannel","file":"src/core/ext/filters/client_channel/client_channel.cc","file_line":3186,"referenced_errors":[{"created":"@1665704187.535854337","description":"failed to connect to all addresses","file":"src/core/lib/transport/error_utils.cc","file_line":146,"grpc_status":14}]}"
>. Will retry in 5 sec.
(10-13) 19:36:27 WARNING  [executor.py:399] Failed to connect to aggregator <_InactiveRpcError of RPC that terminated with:
	status = StatusCode.UNAVAILABLE
	details = "failed to connect to all addresses"
	debug_error_string = "{"created":"@1665704187.535867100","description":"Failed to pick subchannel","file":"src/core/ext/filters/client_channel/client_channel.cc","file_line":3186,"referenced_errors":[{"created":"@1665704187.535866023","description":"failed to connect to all addresses","file":"src/core/lib/transport/error_utils.cc","file_line":146,"grpc_status":14}]}"
>. Will retry in 5 sec.
(10-13) 19:36:32 WARNING  [executor.py:399] Failed to connect to aggregator <_InactiveRpcError of RPC that terminated with:
	status = StatusCode.UNAVAILABLE
	details = "failed to connect to all addresses"
	debug_error_string = "{"created":"@1665704192.538981257","description":"Failed to pick subchannel","file":"src/core/ext/filters/client_channel/client_channel.cc","file_line":3186,"referenced_errors":[{"created":"@1665704192.538979688","description":"failed to connect to all addresses","file":"src/core/lib/transport/error_utils.cc","file_line":146,"grpc_status":14}]}"
>. Will retry in 5 sec.
(10-13) 19:36:32 WARNING  [executor.py:399] Failed to connect to aggregator <_InactiveRpcError of RPC that terminated with:
	status = StatusCode.UNAVAILABLE
	details = "failed to connect to all addresses"
	debug_error_string = "{"created":"@1665704192.538981377","description":"Failed to pick subchannel","file":"src/core/ext/filters/client_channel/client_channel.cc","file_line":3186,"referenced_errors":[{"created":"@1665704192.538979719","description":"failed to connect to all addresses","file":"src/core/lib/transport/error_utils.cc","file_line":146,"grpc_status":14}]}"
>. Will retry in 5 sec.
(10-13) 19:36:32 WARNING  [executor.py:399] Failed to connect to aggregator <_InactiveRpcError of RPC that terminated with:
	status = StatusCode.UNAVAILABLE
	details = "failed to connect to all addresses"
	debug_error_string = "{"created":"@1665704192.539948174","description":"Failed to pick subchannel","file":"src/core/ext/filters/client_channel/client_channel.cc","file_line":3186,"referenced_errors":[{"created":"@1665704192.539946719","description":"failed to connect to all addresses","file":"src/core/lib/transport/error_utils.cc","file_line":146,"grpc_status":14}]}"
>. Will retry in 5 sec.
(10-13) 19:36:32 WARNING  [executor.py:399] Failed to connect to aggregator <_InactiveRpcError of RPC that terminated with:
	status = StatusCode.UNAVAILABLE
	details = "failed to connect to all addresses"
	debug_error_string = "{"created":"@1665704192.539948143","description":"Failed to pick subchannel","file":"src/core/ext/filters/client_channel/client_channel.cc","file_line":3186,"referenced_errors":[{"created":"@1665704192.539947036","description":"failed to connect to all addresses","file":"src/core/lib/transport/error_utils.cc","file_line":146,"grpc_status":14}]}"
>. Will retry in 5 sec.
(10-13) 19:36:37 WARNING  [executor.py:399] Failed to connect to aggregator <_InactiveRpcError of RPC that terminated with:
	status = StatusCode.UNAVAILABLE
	details = "failed to connect to all addresses"
	debug_error_string = "{"created":"@1665704197.542882324","description":"Failed to pick subchannel","file":"src/core/ext/filters/client_channel/client_channel.cc","file_line":3186,"referenced_errors":[{"created":"@1665704197.542880900","description":"failed to connect to all addresses","file":"src/core/lib/transport/error_utils.cc","file_line":146,"grpc_status":14}]}"
>. Will retry in 5 sec.
(10-13) 19:36:37 WARNING  [executor.py:399] Failed to connect to aggregator <_InactiveRpcError of RPC that terminated with:
	status = StatusCode.UNAVAILABLE
	details = "failed to connect to all addresses"
	debug_error_string = "{"created":"@1665704197.542882264","description":"Failed to pick subchannel","file":"src/core/ext/filters/client_channel/client_channel.cc","file_line":3186,"referenced_errors":[{"created":"@1665704197.542880731","description":"failed to connect to all addresses","file":"src/core/lib/transport/error_utils.cc","file_line":146,"grpc_status":14}]}"
>. Will retry in 5 sec.
(10-13) 19:36:37 WARNING  [executor.py:399] Failed to connect to aggregator <_InactiveRpcError of RPC that terminated with:
	status = StatusCode.UNAVAILABLE
	details = "failed to connect to all addresses"
	debug_error_string = "{"created":"@1665704197.544961719","description":"Failed to pick subchannel","file":"src/core/ext/filters/client_channel/client_channel.cc","file_line":3186,"referenced_errors":[{"created":"@1665704197.544960209","description":"failed to connect to all addresses","file":"src/core/lib/transport/error_utils.cc","file_line":146,"grpc_status":14}]}"
>. Will retry in 5 sec.
(10-13) 19:36:37 WARNING  [executor.py:399] Failed to connect to aggregator <_InactiveRpcError of RPC that terminated with:
	status = StatusCode.UNAVAILABLE
	details = "failed to connect to all addresses"
	debug_error_string = "{"created":"@1665704197.545124235","description":"Failed to pick subchannel","file":"src/core/ext/filters/client_channel/client_channel.cc","file_line":3186,"referenced_errors":[{"created":"@1665704197.545123039","description":"failed to connect to all addresses","file":"src/core/lib/transport/error_utils.cc","file_line":146,"grpc_status":14}]}"
>. Will retry in 5 sec.
(10-13) 19:36:42 WARNING  [executor.py:399] Failed to connect to aggregator <_InactiveRpcError of RPC that terminated with:
	status = StatusCode.UNAVAILABLE
	details = "failed to connect to all addresses"
	debug_error_string = "{"created":"@1665704202.546770673","description":"Failed to pick subchannel","file":"src/core/ext/filters/client_channel/client_channel.cc","file_line":3186,"referenced_errors":[{"created":"@1665704202.546769939","description":"failed to connect to all addresses","file":"src/core/lib/transport/error_utils.cc","file_line":146,"grpc_status":14}]}"
>. Will retry in 5 sec.
(10-13) 19:36:42 WARNING  [executor.py:399] Failed to connect to aggregator <_InactiveRpcError of RPC that terminated with:
	status = StatusCode.UNAVAILABLE
	details = "failed to connect to all addresses"
	debug_error_string = "{"created":"@1665704202.547269885","description":"Failed to pick subchannel","file":"src/core/ext/filters/client_channel/client_channel.cc","file_line":3186,"referenced_errors":[{"created":"@1665704202.547269218","description":"failed to connect to all addresses","file":"src/core/lib/transport/error_utils.cc","file_line":146,"grpc_status":14}]}"
>. Will retry in 5 sec.
(10-13) 19:36:42 WARNING  [executor.py:399] Failed to connect to aggregator <_InactiveRpcError of RPC that terminated with:
	status = StatusCode.UNAVAILABLE
	details = "failed to connect to all addresses"
	debug_error_string = "{"created":"@1665704202.550730397","description":"Failed to pick subchannel","file":"src/core/ext/filters/client_channel/client_channel.cc","file_line":3186,"referenced_errors":[{"created":"@1665704202.550729818","description":"failed to connect to all addresses","file":"src/core/lib/transport/error_utils.cc","file_line":146,"grpc_status":14}]}"
>. Will retry in 5 sec.
(10-13) 19:36:42 WARNING  [executor.py:399] Failed to connect to aggregator <_InactiveRpcError of RPC that terminated with:
	status = StatusCode.UNAVAILABLE
	details = "failed to connect to all addresses"
	debug_error_string = "{"created":"@1665704202.551195511","description":"Failed to pick subchannel","file":"src/core/ext/filters/client_channel/client_channel.cc","file_line":3186,"referenced_errors":[{"created":"@1665704202.551194912","description":"failed to connect to all addresses","file":"src/core/lib/transport/error_utils.cc","file_line":146,"grpc_status":14}]}"
>. Will retry in 5 sec.
(10-13) 19:36:43 INFO     [aggregator.py:129] Initiating control plane communication ...
(10-13) 19:36:43 INFO     [aggregator.py:153] %%%%%%%%%% Opening aggregator sever using port [::]:29501 %%%%%%%%%%
(10-13) 19:36:43 INFO     [fllibs.py:119] Initializing the model ...
(10-13) 19:36:47 WARNING  [executor.py:399] Failed to connect to aggregator <_InactiveRpcError of RPC that terminated with:
	status = StatusCode.UNAVAILABLE
	details = "failed to connect to all addresses"
	debug_error_string = "{"created":"@1665704207.550881740","description":"Failed to pick subchannel","file":"src/core/ext/filters/client_channel/client_channel.cc","file_line":3186,"referenced_errors":[{"created":"@1665704207.550880049","description":"failed to connect to all addresses","file":"src/core/lib/transport/error_utils.cc","file_line":146,"grpc_status":14}]}"
>. Will retry in 5 sec.
(10-13) 19:36:47 WARNING  [executor.py:399] Failed to connect to aggregator <_InactiveRpcError of RPC that terminated with:
	status = StatusCode.UNAVAILABLE
	details = "failed to connect to all addresses"
	debug_error_string = "{"created":"@1665704207.550881623","description":"Failed to pick subchannel","file":"src/core/ext/filters/client_channel/client_channel.cc","file_line":3186,"referenced_errors":[{"created":"@1665704207.550879979","description":"failed to connect to all addresses","file":"src/core/lib/transport/error_utils.cc","file_line":146,"grpc_status":14}]}"
>. Will retry in 5 sec.
(10-13) 19:36:47 WARNING  [executor.py:399] Failed to connect to aggregator <_InactiveRpcError of RPC that terminated with:
	status = StatusCode.UNAVAILABLE
	details = "failed to connect to all addresses"
	debug_error_string = "{"created":"@1665704207.554962370","description":"Failed to pick subchannel","file":"src/core/ext/filters/client_channel/client_channel.cc","file_line":3186,"referenced_errors":[{"created":"@1665704207.554960939","description":"failed to connect to all addresses","file":"src/core/lib/transport/error_utils.cc","file_line":146,"grpc_status":14}]}"
>. Will retry in 5 sec.
(10-13) 19:36:47 WARNING  [executor.py:399] Failed to connect to aggregator <_InactiveRpcError of RPC that terminated with:
	status = StatusCode.UNAVAILABLE
	details = "failed to connect to all addresses"
	debug_error_string = "{"created":"@1665704207.554962464","description":"Failed to pick subchannel","file":"src/core/ext/filters/client_channel/client_channel.cc","file_line":3186,"referenced_errors":[{"created":"@1665704207.554960934","description":"failed to connect to all addresses","file":"src/core/lib/transport/error_utils.cc","file_line":146,"grpc_status":14}]}"
>. Will retry in 5 sec.
(10-13) 19:36:50 INFO     [aggregator.py:871] Start monitoring events ...
(10-13) 19:36:52 WARNING  [executor.py:399] Failed to connect to aggregator <_InactiveRpcError of RPC that terminated with:
	status = StatusCode.UNAVAILABLE
	details = "failed to connect to all addresses"
	debug_error_string = "{"created":"@1665704212.556953398","description":"Failed to pick subchannel","file":"src/core/ext/filters/client_channel/client_channel.cc","file_line":3186,"referenced_errors":[{"created":"@1665704212.556951745","description":"failed to connect to all addresses","file":"src/core/lib/transport/error_utils.cc","file_line":146,"grpc_status":14}]}"
>. Will retry in 5 sec.
(10-13) 19:36:52 WARNING  [executor.py:399] Failed to connect to aggregator <_InactiveRpcError of RPC that terminated with:
	status = StatusCode.UNAVAILABLE
	details = "failed to connect to all addresses"
	debug_error_string = "{"created":"@1665704212.556953405","description":"Failed to pick subchannel","file":"src/core/ext/filters/client_channel/client_channel.cc","file_line":3186,"referenced_errors":[{"created":"@1665704212.556951925","description":"failed to connect to all addresses","file":"src/core/lib/transport/error_utils.cc","file_line":146,"grpc_status":14}]}"
>. Will retry in 5 sec.
(10-13) 19:36:52 WARNING  [executor.py:399] Failed to connect to aggregator <_InactiveRpcError of RPC that terminated with:
	status = StatusCode.UNAVAILABLE
	details = "failed to connect to all addresses"
	debug_error_string = "{"created":"@1665704212.557918447","description":"Failed to pick subchannel","file":"src/core/ext/filters/client_channel/client_channel.cc","file_line":3186,"referenced_errors":[{"created":"@1665704212.557917134","description":"failed to connect to all addresses","file":"src/core/lib/transport/error_utils.cc","file_line":146,"grpc_status":14}]}"
>. Will retry in 5 sec.
(10-13) 19:36:52 INFO     [aggregator.py:263] Received executor 1 information, 1/4
(10-13) 19:36:57 INFO     [aggregator.py:263] Received executor 4 information, 2/4
(10-13) 19:36:57 INFO     [aggregator.py:263] Received executor 2 information, 3/4
(10-13) 19:36:57 INFO     [aggregator.py:234] Loading 10 client traces ...
(10-13) 19:36:57 INFO     [aggregator.py:263] Received executor 3 information, 4/4
(10-13) 19:36:57 INFO     [aggregator.py:251] Info of all feasible clients {'total_feasible_clients': 10, 'total_num_samples': 97329}
(10-13) 19:36:57 INFO     [aggregator.py:234] Loading 10 client traces ...
(10-13) 19:36:57 INFO     [aggregator.py:529] Wall clock: 0 s, round: 1, Planned participants: 0, Succeed participants: 0, Training loss: 0.0
(10-13) 19:36:57 INFO     [aggregator.py:251] Info of all feasible clients {'total_feasible_clients': 20, 'total_num_samples': 194658}
(10-13) 19:36:57 INFO     [client_manager.py:202] Wall clock time: 0, 7 clients online, 13 clients offline
(10-13) 19:36:57 INFO     [aggregator.py:541] Selected participants to run: [15, 13, 5, 10, 16, 6, 4]
(10-13) 19:36:57 INFO     [aggregator.py:529] Wall clock: 0 s, round: 2, Planned participants: 7, Succeed participants: 0, Training loss: 0.0
(10-13) 19:36:57 INFO     [client_manager.py:202] Wall clock time: 0, 7 clients online, 13 clients offline
(10-13) 19:36:57 INFO     [aggregator.py:541] Selected participants to run: [15, 13, 5, 10, 16, 6, 4]
(10-13) 19:36:58 INFO     [aggregator.py:804] ====event queue 4, deque(['update_model', 'client_train', 'update_model', 'client_train'])
(10-13) 19:36:58 INFO     [aggregator.py:827] Issue EVENT (update_model) to EXECUTOR (4)
(10-13) 19:36:58 INFO     [aggregator.py:804] ====event queue 2, deque(['update_model', 'client_train', 'update_model', 'client_train'])
(10-13) 19:36:58 INFO     [aggregator.py:827] Issue EVENT (update_model) to EXECUTOR (2)
(10-13) 19:36:58 INFO     [aggregator.py:804] ====event queue 3, deque(['update_model', 'client_train', 'update_model', 'client_train'])
(10-13) 19:36:58 INFO     [aggregator.py:827] Issue EVENT (update_model) to EXECUTOR (3)
(10-13) 19:36:58 INFO     [aggregator.py:804] ====event queue 1, deque(['update_model', 'client_train', 'update_model', 'client_train'])
(10-13) 19:36:58 INFO     [aggregator.py:827] Issue EVENT (update_model) to EXECUTOR (1)
(10-13) 19:37:00 INFO     [aggregator.py:804] ====event queue 1, deque(['client_train', 'update_model', 'client_train'])
(10-13) 19:37:00 INFO     [aggregator.py:827] Issue EVENT (client_train) to EXECUTOR (1)
(10-13) 19:37:00 INFO     [aggregator.py:804] ====event queue 2, deque(['client_train', 'update_model', 'client_train'])
(10-13) 19:37:00 INFO     [aggregator.py:827] Issue EVENT (client_train) to EXECUTOR (2)
(10-13) 19:37:00 INFO     [aggregator.py:804] ====event queue 3, deque(['client_train', 'update_model', 'client_train'])
(10-13) 19:37:00 INFO     [aggregator.py:827] Issue EVENT (client_train) to EXECUTOR (3)
(10-13) 19:37:00 INFO     [aggregator.py:804] ====event queue 4, deque(['client_train', 'update_model', 'client_train'])
(10-13) 19:37:00 INFO     [aggregator.py:827] Issue EVENT (client_train) to EXECUTOR (4)
Traceback (most recent call last):
  File "/u/utd8hj/Documents/FedScale/fedscale/core/execution/executor.py", line 455, in <module>
    executor.run()
  File "/u/utd8hj/Documents/FedScale/fedscale/core/execution/executor.py", line 143, in run
    self.event_monitor()
  File "/u/utd8hj/Documents/FedScale/fedscale/core/execution/executor.py", line 426, in event_monitor
    client_id, train_res = self.Train(train_config)
  File "/u/utd8hj/Documents/FedScale/fedscale/core/execution/executor.py", line 205, in Train
    clientId=client_id, conf=client_conf, model=model)
  File "/u/utd8hj/Documents/FedScale/fedscale/core/execution/executor.py", line 331, in training_handler
    collate_fn=self.collate_fn
  File "/u/utd8hj/Documents/FedScale/fedscale/dataloaders/divide_data.py", line 133, in select_dataset
    partition = partition.use(rank - 1, isTest)
  File "/u/utd8hj/Documents/FedScale/fedscale/dataloaders/divide_data.py", line 117, in use
    resultIndex = self.partitions[partition]
IndexError: list index out of range
(10-13) 19:37:00 INFO     [client.py:32] Start to train (CLIENT: 10) ...
Traceback (most recent call last):
  File "/u/utd8hj/Documents/FedScale/fedscale/core/execution/executor.py", line 455, in <module>
    executor.run()
  File "/u/utd8hj/Documents/FedScale/fedscale/core/execution/executor.py", line 143, in run
    self.event_monitor()
  File "/u/utd8hj/Documents/FedScale/fedscale/core/execution/executor.py", line 426, in event_monitor
    client_id, train_res = self.Train(train_config)
  File "/u/utd8hj/Documents/FedScale/fedscale/core/execution/executor.py", line 205, in Train
    clientId=client_id, conf=client_conf, model=model)
  File "/u/utd8hj/Documents/FedScale/fedscale/core/execution/executor.py", line 331, in training_handler
    collate_fn=self.collate_fn
  File "/u/utd8hj/Documents/FedScale/fedscale/dataloaders/divide_data.py", line 133, in select_dataset
    partition = partition.use(rank - 1, isTest)
  File "/u/utd8hj/Documents/FedScale/fedscale/dataloaders/divide_data.py", line 117, in use
    resultIndex = self.partitions[partition]
IndexError: list index out of range
(10-13) 19:37:00 INFO     [client.py:32] Start to train (CLIENT: 5) ...
/u/utd8hj/miniconda3/envs/fedscale/lib/python3.7/site-packages/torch/cuda/__init__.py:146: UserWarning: 
NVIDIA A40 with CUDA capability sm_86 is not compatible with the current PyTorch installation.
The current PyTorch install supports CUDA capabilities sm_37 sm_50 sm_60 sm_70.
If you want to use the NVIDIA A40 GPU with PyTorch, please check the instructions at https://pytorch.org/get-started/locally/

  warnings.warn(incompatible_device_warn.format(device_name, capability, " ".join(arch_list), device_name))
/u/utd8hj/miniconda3/envs/fedscale/lib/python3.7/site-packages/torch/cuda/__init__.py:146: UserWarning: 
NVIDIA A40 with CUDA capability sm_86 is not compatible with the current PyTorch installation.
The current PyTorch install supports CUDA capabilities sm_37 sm_50 sm_60 sm_70.
If you want to use the NVIDIA A40 GPU with PyTorch, please check the instructions at https://pytorch.org/get-started/locally/

  warnings.warn(incompatible_device_warn.format(device_name, capability, " ".join(arch_list), device_name))
(10-13) 19:37:10 INFO     [client.py:69] Training of (CLIENT: 5) failed as CUDA error: no kernel image is available for execution on the device
CUDA kernel errors might be asynchronously reported at some other API call,so the stacktrace below might be incorrect.
For debugging consider passing CUDA_LAUNCH_BLOCKING=1.
(10-13) 19:37:10 INFO     [aggregator.py:804] ====event queue 3, deque(['update_model', 'client_train'])
(10-13) 19:37:10 INFO     [aggregator.py:827] Issue EVENT (update_model) to EXECUTOR (3)
(10-13) 19:37:10 INFO     [aggregator.py:804] ====event queue 3, deque(['client_train'])
(10-13) 19:37:10 INFO     [aggregator.py:827] Issue EVENT (client_train) to EXECUTOR (3)
(10-13) 19:37:10 INFO     [client.py:69] Training of (CLIENT: 10) failed as CUDA error: no kernel image is available for execution on the device
CUDA kernel errors might be asynchronously reported at some other API call,so the stacktrace below might be incorrect.
For debugging consider passing CUDA_LAUNCH_BLOCKING=1.
(10-13) 19:37:10 INFO     [aggregator.py:804] ====event queue 4, deque(['update_model', 'client_train'])
(10-13) 19:37:10 INFO     [aggregator.py:827] Issue EVENT (update_model) to EXECUTOR (4)
Traceback (most recent call last):
  File "/u/utd8hj/Documents/FedScale/fedscale/core/execution/executor.py", line 455, in <module>
    executor.run()
  File "/u/utd8hj/Documents/FedScale/fedscale/core/execution/executor.py", line 143, in run
    self.event_monitor()
  File "/u/utd8hj/Documents/FedScale/fedscale/core/execution/executor.py", line 426, in event_monitor
    client_id, train_res = self.Train(train_config)
  File "/u/utd8hj/Documents/FedScale/fedscale/core/execution/executor.py", line 205, in Train
    clientId=client_id, conf=client_conf, model=model)
  File "/u/utd8hj/Documents/FedScale/fedscale/core/execution/executor.py", line 331, in training_handler
    collate_fn=self.collate_fn
  File "/u/utd8hj/Documents/FedScale/fedscale/dataloaders/divide_data.py", line 133, in select_dataset
    partition = partition.use(rank - 1, isTest)
  File "/u/utd8hj/Documents/FedScale/fedscale/dataloaders/divide_data.py", line 117, in use
    resultIndex = self.partitions[partition]
IndexError: list index out of range
(10-13) 19:37:10 INFO     [aggregator.py:804] ====event queue 4, deque(['client_train'])
(10-13) 19:37:10 INFO     [aggregator.py:827] Issue EVENT (client_train) to EXECUTOR (4)
(10-13) 19:37:10 INFO     [client.py:32] Start to train (CLIENT: 6) ...
(10-13) 19:37:10 INFO     [client.py:69] Training of (CLIENT: 6) failed as CUDA error: no kernel image is available for execution on the device
CUDA kernel errors might be asynchronously reported at some other API call,so the stacktrace below might be incorrect.
For debugging consider passing CUDA_LAUNCH_BLOCKING=1.
(10-13) 19:37:10 INFO     [aggregator.py:804] ====event queue 4, deque(['client_train'])
(10-13) 19:37:10 INFO     [aggregator.py:827] Issue EVENT (client_train) to EXECUTOR (4)
(10-13) 19:37:10 INFO     [client.py:32] Start to train (CLIENT: 4) ...
(10-13) 19:37:10 INFO     [client.py:69] Training of (CLIENT: 4) failed as CUDA error: no kernel image is available for execution on the device
CUDA kernel errors might be asynchronously reported at some other API call,so the stacktrace below might be incorrect.
For debugging consider passing CUDA_LAUNCH_BLOCKING=1.
Host key verification failed.
(10-13) 19:39:17 INFO     [aggregator.py:775] Previous client: 4 resumes connecting
(10-13) 19:39:17 INFO     [aggregator.py:263] Received executor 4 information, 4/4
(10-13) 19:39:17 INFO     [aggregator.py:234] Loading 10 client traces ...
(10-13) 19:39:17 INFO     [aggregator.py:251] Info of all feasible clients {'total_feasible_clients': 30, 'total_num_samples': 291987}
(10-13) 19:39:17 INFO     [aggregator.py:529] Wall clock: 45 s, round: 3, Planned participants: 7, Succeed participants: 4, Training loss: 0.0001
(10-13) 19:39:17 INFO     [client_manager.py:202] Wall clock time: 45, 12 clients online, 18 clients offline
(10-13) 19:39:17 INFO     [aggregator.py:541] Selected participants to run: [15, 13, 5, 26, 2, 12, 24, 10, 16, 6, 4, 30]
(10-13) 19:39:18 INFO     [aggregator.py:804] ====event queue 4, deque(['update_model', 'client_train'])
(10-13) 19:39:18 INFO     [aggregator.py:827] Issue EVENT (update_model) to EXECUTOR (4)
(10-13) 19:39:18 INFO     [aggregator.py:804] ====event queue 4, deque(['client_train'])
(10-13) 19:39:18 INFO     [aggregator.py:827] Issue EVENT (client_train) to EXECUTOR (4)
